Workbook

Sheet CABAC Fiduciary 2025
A2: COMPARATIVE APPROVED BUDGET and ACTUAL COLLECTION
A3: INTERNALLY GENERATED FUNDS (IGF) - Fiduciary Fees
A5: CY 2025
A6: EVSU ORMOC CAMPUS | V6: Page 1 of 7
E7: Approved | G7: A L L O T M E N T
E8: Budget | F8: Total | G8: (ACTUAL COLLECTION)
A9: PROGRAM / ACTIVITY | D9: Fiduciary | E9: (Based on | F9: Available | J9: FHE
D10: Fees | E10: Estimated | F10: Allotment | G10: Jan | H10: Feb | I10: March | J10: 41334 | K10: Apr | L10: May | M10: June | N10: July | O10: August | P10: Sept | Q10: Oct | R10: FHE | S10: Nov | T10: Nov | U10: Dec | V10: Balance
E11: Collection) | J11: 2025 | R11: SS 2024-2025 | Z11: =X11+X12 -> 0
A12: I. | B12: Personnel Services (PS)
B13: Honoraria - Overload | D13: Laboratory | E13: 2000000 | F13: =SUM(G13:U13) -> 2000000 | J13: 2000000 | V13: =E13-F13 -> 0
V14: =E14-F14 -> 0
B15: Honoraria - Part-time | D15: Laboratory | E15: 3000000 | F15: =SUM(G15:U15) -> 1082651 | J15: 1082651 | V15: =E15-F15 -> 1917349
D16: Development Fee | E16: 2000000 | F16: =SUM(G16:U16) -> 2000000 | J16: 2000000 | V16: =E16-F16 -> 0
D17: Computer Fee | E17: 361755 | F17: =SUM(G17:U17) -> 313585.15 | J17: 313585.15 | V17: =E17-F17 -> 48169.85
V18: =E18-F18 -> 0
B19: Honoraria | D19: NSTP | E19: 400000 | F19: =SUM(G19:U19) -> 196781.93 | J19: =125150+10000+26000+11631.93+24000 -> 196781.93 | V19: =E19-F19 -> 203218.07
D20: Athletic | E20: 173468.66 | F20: =SUM(G20:U20) -> 99503.1 | G20: 900 | J20: =76.66+98526.44 -> 98603.1 | V20: =E20-F20 -> 73965.56
D21: Cultural | E21: 100000 | F21: =SUM(G21:U21) -> 100 | M21: 100 | V21: =E21-F21 -> 99900
D22: Computer/ Internet | F22: =SUM(G22:U22) -> 0 | V22: =E22-F22 -> 0
D23: Dev Fee | F23: =SUM(G23:U23) -> 0 | V23: =E23-F23 -> 0
D24: Grad School | F24: =SUM(G24:U24) -> 0 | V24: =E24-F24 -> 0
D25: SLD | F25: =SUM(G25:U25) -> 0 | V25: =E25-F25 -> 0
D26: Senior High | F26: =SUM(G26:U26) -> 0 | V26: =E26-F26 -> 0
D27: School Organ Fee | F27: =SUM(G27:U27) -> 0 | V27: =E27-F27 -> 0
D28: Guidance | E28: 5000 | F28: =SUM(G28:U28) -> 0 | V28: =E28-F28 -> 5000
D29: Compre Exam | F29: =SUM(G29:U29) -> 0 | V29: =E29-F29 -> 0
D30: GS/Defense fee | F30: =SUM(G30:U30) -> 0 | V30: =E30-F30 -> 0
D31: Petition | F31: =SUM(G31:U31) -> 186834 | G31: =5050+4200+91180 -> 100430 | H31: =16364+70040 -> 86404 | V31: =E31-F31 -> -186834
D32: OJT/Practicum | E32: 321600 | F32: =SUM(G32:U32) -> 208500 | G32: =26500+4000+110000+68000 -> 208500 | V32: =E32-F32 -> 113100
E33: =SUM(E13:E32) -> 8361823.7 | F33: =SUM(F13:F32) -> 6087955.1 | G33: =SUM(G19:G32) -> 309830 | H33: =SUM(H19:H32) -> 86404 | I33: =SUM(I19:I32) -> 0 | J33: =SUM(J13:J32) -> 5691621.1 | K33: =SUM(K19:K32) -> 0 | L33: =SUM(L19:L32) -> 0 | M33: =SUM(M19:M32) -> 100 | N33: =SUM(N19:N32) -> 0 | O33: =SUM(O19:O32) -> 0 | P33: =SUM(P19:P32) -> 0 | Q33: =SUM(Q19:Q32) -> 0 | R33: =SUM(R19:R32) -> 0 | ... U33: =SUM(U19:U32) -> 0 | V33: =SUM(V13:V32) -> 2273868.5
A34: II. | B34: Maintenance and Other
B35: Operating Expenses
B36: (MOOE)
B37: Traveling Expenses | D37: NSTP | E37: 59000 | F37: =SUM(G37:U37) -> 59000 | J37: 59000 | V37: =E37-F37 -> 0
D38: Athletics | E38: 364436.8 | F38: =SUM(G38:U38) -> 364436.8 | J38: 364436.8 | V38: =E38-F38 -> 0
D39: SCUAA | E39: 147240 | F39: =SUM(G39:U39) -> 180876.64 | G39: 90000 | J39: 87996.64 | M39: =2880 -> 2880 | V39: =E39-F39 -> -33636.64
D40: Comp Fee | E40: 300000 | F40: =SUM(G40:U40) -> 194368.72 | J40: 194368.72 | V40: =E40-F40 -> 105631.28
D41: Cultural | E41: 217414.54 | F41: =SUM(G41:U41) -> 218314.54 | G41: 900 | J41: 217414.54 | V41: =E41-F41 -> -900
D42: Dev Fee | E42: 150000 | F42: =SUM(G42:U42) -> 3000 | G42: 3000 | V42: =E42-F42 -> 147000
...

Sheet CABAC Non-Fid 2025
A2: COMPARATIVE APPROVED BUDGET and ACTUAL COLLECTION
A3: INTERNALLY GENERATED FUNDS (IGF)
A4: Non-Fiduciary
A5: CY 2025 | V5: Page 1 of 3
A6: EVSU ORMOC CAMPUS
E7: Approved | H7: A L L O T M E N T
E8: Budget | G8: Total | H8: (ACTUAL COLLECTION)
A9: Particulars | E9: (Based on | F9: Programs | G9: Available | K9: FHE March 13,2025 | S9: FHE
E10: Estimated | G10: Allotment | H10: Jan | I10: Feb | J10: Mar | L10: Apr | M10: May | N10: June | O10: July | P10: August | Q10: Sep | R10: Oct | S10: SS 2023-2024 | T10: Nov | U10: Dec | V10: Balance
E11: Collection)
A12: I. Personnel Services (PS) | E12: =E21 -> 7103777.5 | F12: =F21 -> 0 | G12: =G21 -> 3509675.9 | H12: =H21 -> 0 | I12: =I21 -> 0 | J12: =J21 -> 0 | L12: =L21 -> 13224 | M12: =M21 -> 15529.75 | N12: =N21 -> 72895.88 | O12: =O21 -> 0 | P12: =P21 -> 0 | Q12: =Q21 -> 0 | R12: =R21 -> 0 | S12: =S21 -> 0 | ... V12: =V21 -> 3594101.6
A13: Honoraria | E13: 2000000 | F13: Fac & Staff Dev | G13: =SUM(H13:U13) -> 1528875 | K13: 1461851.2 | L13: 9280 | M13: 6588.75 | N13: 51155 | V13: =E13-G13 -> 471125
E14: 4487201.2 | F14: Curr Devt | G14: =SUM(H14:U14) -> 1574857.2 | K14: 1546175 | L14: 3248 | M14: 7530 | N14: 17904.25 | V14: =E14-G14 -> 2912344
E15: 16576.22 | F15: Student Dev | G15: =SUM(H15:U15) -> 5943.63 | L15: 696 | M15: 1411 | N15: 3836.63 | V15: =E15-G15 -> 10632.59
E16: 300000 | F16: Research | G16: =SUM(H16:U16) -> 200000 | K16: 200000 | V16: =E16-G16 -> 100000
E17: 300000 | F17: Extension | G17: =SUM(H17:U17) -> 200000 | K17: 200000 | V17: =E17-G17 -> 100000
F18: GS | G18: =SUM(H18:U18) -> 0 | V18: =E18-G18 -> 0
F19: Petition | G19: =SUM(H19:U19) -> 0 | V19: =E19-G19 -> 0
F20: Admin | G20: =SUM(H20:U20) -> 0 | V20: =E20-G20 -> 0
E21: =SUM(E13:E20) -> 7103777.5 | F21: =SUM(F13:F20) -> 0 | G21: =SUM(G13:G20) -> 3509675.9 | H21: =SUM(H13:H20) -> 0 | I21: =SUM(I13:I20) -> 0 | J21: =SUM(J13:J20) -> 0 | K21: =SUM(K13:K20) -> 3408026.2 | L21: =SUM(L13:L20) -> 13224 | ... V21: =SUM(V13:V20) -> 3594101.6
A22: II. Maintenance and Other Operating
A23: Expenses (MOOE) | E23: =E32+E38+E47+E50+E61+E67+E77+E79+E86+E92+E98+E100+E115+E121+E130+E132+E141+E143+E148+E155+E160+E162+E169+E177+E183+E199+E202+E215+E150+E195+E126 -> 18440309 | G23: =G32+G38+G47+G50+G61+G67+G77+G79+G86+G92+G98+G100+G115+G121+G130+G132+G141+G143+G148+G155+G160+G162+G169+G177+G183+G199+G202+G215+G150+G195+G126 -> 0 | H23: =H32+H38+H47+H50+H61+H67+H77+H79+H86+H92+H98+H100+H115+H121+H130+H132+H141+H143+H148+H155+H160+H162+H169+H177+H183+H199+H202+H215+H150+H195+H126 -> 0 | I23: =I32+I38+I47+I50+I61+I67+I77+I79+I86+I92+I98+I100+I115+I121+I130+I132+I141+I143+I148+I155+I160+I162+I169+I177+I183+I199+I202+I215+I150+I195+I126 -> 0 | J23: =J32+J38+J47+J50+J61+J67+J77+J79+J86+J92+J98+J100+J115+J121+J130+J132+J141+J143+J148+J155+J160+J162+J169+J177+J183+J199+J202+J215+J150+J195+J126 -> 0 | L23: =L32+L38+L47+L50+L61+L67+L77+L79+L86+L92+L98+L100+L115+L121+L130+L132+L141+L143+L148+L155+L160+L162+L169+L177+L183+L199+L202+L215+L150+L195+L126 -> 0 | M23: =M32+M38+M47+M50+M61+M67+M77+M79+M86+M92+M98+M100+M115+M121+M130+M132+M141+M143+M148+M155+M160+M162+M169+M177+M183+M199+M202+M215+M150+M195+M126 -> 0 | N23: =N32+N38+N47+N50+N61+N67+N77+N79+N86+N92+N98+N100+N115+N121+N130+N132+N141+N143+N148+N155+N160+N162+N169+N177+N183+N199+N202+N215+N150+N195+N126 -> 0 | O23: =O32+O38+O47+O50+O61+O67+O77+O79+O86+O92+O98+O100+O115+O121+O130+O132+O141+O143+O148+O155+O160+O162+O169+O177+O183+O199+O202+O215+O150+O195+O126 -> 0 | P23: =P32+P38+P47+P50+P61+P67+P77+P79+P86+P92+P98+P100+P115+P121+P130+P132+P141+P143+P148+P155+P160+P162+P169+P177+P183+P199+P202+P215+P150+P195+P126 -> 0 | Q23: =Q32+Q38+Q47+Q50+Q61+Q67+Q77+Q79+Q86+Q92+Q98+Q100+Q115+Q121+Q130+Q132+Q141+Q143+Q148+Q155+Q160+Q162+Q169+Q177+Q183+Q199+Q202+Q215+Q150+Q195+Q126 -> 0 | R23: =R32+R38+R47+R50+R61+R67+R77+R79+R86+R92+R98+R100+R115+R121+R130+R132+R141+R143+R148+R155+R160+R162+R169+R177+R183+R199+R202+R215+R150+R195+R126 -> 0 | S23: =S32+S38+S47+S50+S61+S67+S77+S79+S86+S92+S98+S100+S115+S121+S130+S132+S141+S143+S148+S155+S160+S162+S169+S177+S183+S199+S202+S215+S150+S195+S126 -> 0 | ... U23: =U32+U38+U47+U50+U61+U67+U77+U79+U86+U92+U98+U100+U115+U121+U130+U132+U141+U143+U148+U155+U160+U162+U169+U177+U183+U199+U202+U215+U150+U195+U126 -> 0 | V23: =E23-G23 -> 10943733 | X23: =V32+V38+V47+V50+V61+V67+V77+V79+V86+V92+V98+V100+V115+V121+V128+V132+V141+V148+V150+V155+V160+V162+V164+V169+V177+V183+V199+V202+V215 -> 9417232.2
V24: =E24-G24 -> 0
A25: Traveling Expenses - Local | E25: 500000 | F25: Fac & Staff Dev | G25: =SUM(H25:U25) -> 200000 | K25: 200000 | V25: =E25-G25 -> 300000
E26: 100000 | F26: Curr Devt | G26: =SUM(H26:U26) -> 100000 | K26: 100000 | V26: =E26-G26 -> 0
E27: 181640 | F27: Student Dev | G27: =SUM(H27:U27) -> 100000 | K27: 100000 | V27: =E27-G27 -> 81640
E28: 200000 | F28: Research | G28: =SUM(H28:U28) -> 200000 | K28: 200000 | V28: =E28-G28 -> 0
E29: 400000 | F29: Extension | G29: =SUM(H29:U29) -> 200000 | K29: 200000 | V29: =E29-G29 -> 200000
E30: 99023.88 | F30: Production | G30: =SUM(H30:U30) -> 35000 | K30: 35000 | V30: =E30-G30 -> 64023.88
E31: 400000 | F31: Admin | G31: =SUM(H31:U31) -> 155621 | K31: 150000 | L31: =1856 -> 1856 | M31: 3765 | V31: =E31-G31 -> 244379
E32: =SUM(E25:E31) -> 1880663.9 | G32: =SUM(G25:G31) -> 990621 | H32: =SUM(H25:H31) -> 0 | I32: =SUM(I25:I31) -> 0 | J32: =SUM(J25:J31) -> 0 | K32: =SUM(K25:K31) -> 985000 | L32: =SUM(L25:L31) -> 1856 | M32: =SUM(M25:M31) -> 3765 | N32: =SUM(N25:N31) -> 0 | ... V32: =SUM(V25:V31) -> 890042.88
A34: Traveling Expenses - Foreign | F34: Fac & Staff Dev | G34: =SUM(H34:U34) -> 0 | V34: =E34-G34 -> 0
F35: Curr Devt | G35: =SUM(H35:U35) -> 0 | V35: =E35-G35 -> 0
E36: 200000 | F36: Research | G36: =SUM(H36:U36) -> 103765 | K36: 100000 | M36: 3765 | V36: =E36-G36 -> 96235
F37: Extension | G37: =SUM(H37:U37) -> 0 | V37: =E37-G37 -> 0
E38: =SUM(E34:E37) -> 200000 | G38: =SUM(G34:G37) -> 103765 | H38: =SUM(H34:H37) -> 0 | I38: =SUM(I34:I37) -> 0 | J38: =SUM(J34:J37) -> 0 | K38: =SUM(K34:K37) -> 100000 | L38: =SUM(L34:L37) -> 0 | M38: =SUM(M34:M37) -> 3765 | N38: =SUM(N34:N37) -> 0 | ... V38: =SUM(V34:V37) -> 96235
A40: Training Expenses | E40: 300000 | F40: Fac & Staff Dev | G40: =SUM(H40:U40) -> 100000 | K40: 100000 | V40: =E40-G40 -> 200000
E41: 50000 | F41: Student Dev | G41: =SUM(H41:U41) -> 50000 | K41: 50000 | V41: =E41-G41 -> 0
E42: 100000 | F42: Curr Devt | G42: =SUM(H42:U42) -> 100000 | K42: 100000 | V42: =E42-G42 -> 0
E43: 350000 | F43: Research | G43: =SUM(H43:U43) -> 300000 | K43: 300000 | V43: =E43-G43 -> 50000
...

Sheet IGF Balances Detailed 2025
A2: Internally Generated Funds (IGF)
A3: CY 2024 Detailed Balances
A5: EVSU Main Campus | V5: Page 1 of 20
A6: Particulars | E6: Beginning | F6: Approved Budget | G6: SOF | H6: BOR Res | I6: BOR Res | J6: BOR Res | K6: MAF | L6: MAF | M6: MAF | N6: BOR Res | O6: BOR Res | P6: MAF | Q6: MAF | R6: MAF | S6: MAF | U6: Actual | V6: Ending
E7: Balance | F7: (Actual Collection) | H7: 2024-095 | I7: 2025-002 | R7: INSERT | S7: INSERT | T7: Total | U7: Utilizations | V7: Balance
E8: as of | F8: CY 2025 | R8: ADJUSTMENT | S8: ADJUSTMENT | T8: Available | U8: as of | V8: as of
E9: 01/01/2025 | F9: (As of January 2025) | H9: Dated July 8, 2024 | I9: Dated March 11, 2025 | K9: 001 Dated June 27, 2025 | R9: HERE | S9: HERE | T9: Allotment | U9: December 31, 2025 | V9: =U9 -> December 31, 2025
A10: (1) | E10: (2) | F10: (3) | G10: (4.a) | H10: (4.b) | I10: (5) | J10: (4.c) | K10: (6) | L10: (4.d) | M10: (4.e) | N10: (4.f) | O10: (6) | P10: (6) | Q10: (6) | R10: (6) | S10: (6) | T10: (7)=(2)+(3)+(4)+(5)+(6) | U10: (8) | V10: (9)=(7)-(8)
A11: Personnel Services (PS)
A12: Honoraria | T12: =SUM(E12:S12) -> 0 | V12: =T12-U12 -> 0
A13: 5-01-02-100-01 | B13: Fac & Staff Dev/Curri Dev | E13: =175642.08 -> 175642.08 | F13: ='CABAC Non-Fid 2025'!G13+'CABAC Non-Fid 2025'!G14 -> 3103732.2 | I13: ='CABAC Non-Fid 2025'!K13+'CABAC Non-Fid 2025'!K14 -> 3008026.2 | T13: =SUM(E13:S13) -> 6287400.6 | V13: =T13-U13 -> 6287400.6
B14: Adv Educ | T14: =SUM(E14:S14) -> 0 | V14: =T14-U14 -> 0
B15: Research | E15: 1975445.8 | F15: ='CABAC Non-Fid 2025'!G16 -> 200000 | I15: ='CABAC Non-Fid 2025'!K16 -> 200000 | T15: =SUM(E15:S15) -> 2375445.8 | V15: =T15-U15 -> 2375445.8
B16: Extension | E16: 150000 | F16: ='CABAC Non-Fid 2025'!G17 -> 200000 | I16: ='CABAC Non-Fid 2025'!K17 -> 200000 | T16: =SUM(E16:S16) -> 550000 | V16: =T16-U16 -> 550000
B17: Student Dev Fee ( NF) | E17: 5000 | F17: ='CABAC Non-Fid 2025'!G15 -> 5943.63 | T17: =SUM(E17:S17) -> 10943.63 | V17: =T17-U17 -> 10943.63
B18: Athletic | E18: 143029.2 | F18: ='CABAC Fiduciary 2025'!F20 -> 99503.1 | I18: ='CABAC Fiduciary 2025'!J20 -> 98603.1 | T18: =SUM(E18:S18) -> 341135.4 | V18: =T18-U18 -> 341135.4
B19: Computer Fee | E19: 503376.06 | F19: ='CABAC Fiduciary 2025'!F17 -> 313585.15 | I19: ='CABAC Fiduciary 2025'!J17 -> 313585.15 | T19: =SUM(E19:S19) -> 1130546.4 | V19: =T19-U19 -> 1130546.4
B20: Laboratory Fee | F20: ='CABAC Fiduciary 2025'!F13+'CABAC Fiduciary 2025'!F15 -> 3082651 | I20: ='CABAC Fiduciary 2025'!J13+'CABAC Fiduciary 2025'!J15 -> 3082651 | T20: =SUM(E20:S20) -> 6165301.9 | V20: =T20-U20 -> 6165301.9
B21: Library | E21: 50000 | T21: =SUM(E21:S21) -> 50000 | V21: =T21-U21 -> 50000
B22: Cultural | E22: 200000 | T22: =SUM(E22:S22) -> 200000 | V22: =T22-U22 -> 200000
B23: Guidance Fee | E23: 5000 | T23: =SUM(E23:S23) -> 5000 | V23: =T23-U23 -> 5000
B24: Medical Fee | E24: 90000 | T24: =SUM(E24:S24) -> 90000 | V24: =T24-U24 -> 90000
B25: NSTP Fee | E25: 172563.74 | F25: ='CABAC Fiduciary 2025'!F19 -> 196781.93 | I25: ='CABAC Fiduciary 2025'!J19 -> 196781.93 | T25: =SUM(E25:S25) -> 566127.6 | V25: =T25-U25 -> 566127.6
B26: SCF | E26: 50000 | F26: ='CABAC Fiduciary 2025'!F32 -> 208500 | T26: =SUM(E26:S26) -> 258500 | V26: =T26-U26 -> 258500
B27: SAF | E27: 9778.91 | F27: ='CABAC Fiduciary 2025'!F31+'CABAC Non-Fid 2025'!G19 -> 186834 | T27: =SUM(E27:S27) -> 196612.91 | V27: =T27-U27 -> 196612.91
B28: School Organ Fee | E28: 30000 | T28: =SUM(E28:S28) -> 30000 | V28: =T28-U28 -> 30000
B29: Dev't Fee (F) | F29: ='CABAC Fiduciary 2025'!F16 -> 2000000 | I29: ='CABAC Fiduciary 2025'!J16 -> 2000000 | T29: =SUM(E29:S29) -> 4000000 | V29: =T29-U29 -> 4000000
B30: Sub-Total | E30: =SUM(E12:E29) -> 3559835.8 | F30: =SUM(F12:F29) -> 9597531 | G30: =SUM(G12:G29) -> 0 | H30: =SUM(H12:H29) -> 0 | I30: =SUM(I12:I29) -> 9099647.4 | J30: =SUM(J12:J29) -> 0 | K30: =SUM(K12:K29) -> 0 | L30: =SUM(L12:L29) -> 0 | ... V30: =SUM(V12:V29) -> 22257014
D31: FID | E31: =E18+E19+E20+E21+E22+E23+E24+E25+E26+E27+E28+E29 -> 1253747.9 | F31: =SUM(F18:F29) -> 6087855.2 | G31: =SUM(G18:G29) -> 0 | H31: =SUM(H18:H29) -> 0 | I31: =SUM(I18:I29) -> 5691621.2 | J31: =SUM(J18:J29) -> 0 | K31: =SUM(K18:K29) -> 0 | L31: =SUM(L18:L29) -> 0 | M31: =SUM(M18:M29) -> 0 | ... V31: =SUM(V18:V29) -> 13033224
D32: NF | E32: =E13+E14+E15+E16+E17 -> 2306087.9 | F32: =SUM(F12:F16) -> 3503732.2 | G32: =SUM(G12:G16) -> 0 | H32: =SUM(H12:H16) -> 0 | I32: =SUM(I12:I16) -> 3408026.2 | J32: =SUM(J12:J16) -> 0 | K32: =SUM(K12:K16) -> 0 | L32: =SUM(L12:L16) -> 0 | M32: =SUM(M12:M16) -> 0 | ... V32: =SUM(V12:V16) -> 9212846.4
E33: =SUM(E31:E32) -> 3559835.8 | F33: =SUM(F31:F32) -> 9591587.4 | G33: =SUM(G31:G32) -> 0 | H33: =SUM(H31:H32) -> 0 | I33: =SUM(I31:I32) -> 9099647.4 | J33: =SUM(J31:J32) -> 0 | K33: =SUM(K31:K32) -> 0 | L33: =SUM(L31:L32) -> 0 | ... V33: =SUM(V31:V32) -> 22246071
E34: =E33-E30 -> 0 | F34: =F33-F30 -> -5943.63 | G34: =G33-G30 -> 0 | H34: =H33-H30 -> 0 | I34: =I33-I30 -> 0 | J34: =J33-J30 -> 0 | K34: =K33-K30 -> 0 | L34: =L33-L30 -> 0 | ... V34: =V33-V30 -> -10943.63
A35: Total, PS | E35: =E30 -> 3559835.8 | F35: =F30 -> 9597531 | G35: =G30 -> 0 | H35: =H30 -> 0 | I35: =I30 -> 9099647.4 | J35: =J30 -> 0 | K35: =K30 -> 0 | L35: =L30 -> 0 | ... V35: =V30 -> 22257014
A38: Maintenance and Other Operating Expenses (MOOE)
A40: Travelling Expenses - | B40: GAS | T40: =SUM(E40:S40) -> 0 | V40: =T40-U40 -> 0
A41: Local | B41: Production | E41: 50000 | F41: ='CABAC Non-Fid 2025'!G30 -> 35000 | T41: =SUM(E41:S41) -> 85000 | V41: =T41-U41 -> 85000
A42: 5-02-01-010-00 | B42: Fac & Staff Dev/Curri Dev | E42: =300000+100000 -> 400000 | F42: ='CABAC Non-Fid 2025'!G25+'CABAC Non-Fid 2025'!G26 -> 300000 | T42: =SUM(E42:S42) -> 700000 | V42: =T42-U42 -> 700000
B43: Student Development - NF | E43: 200000 | F43: ='CABAC Non-Fid 2025'!G27 -> 100000 | T43: =SUM(E43:S43) -> 300000 | V43: =T43-U43 -> 300000
B44: Admin | E44: 334226.75 | F44: ='CABAC Non-Fid 2025'!G31 -> 155621 | T44: =SUM(E44:S44) -> 489847.75 | V44: =T44-U44 -> 489847.75
B45: Research | E45: 150000 | F45: ='CABAC Non-Fid 2025'!G28 -> 200000 | T45: =SUM(E45:S45) -> 350000 | V45: =T45-U45 -> 350000
...
